<?xml version="1.0"?>
<robot name="slither">
		

	<link name="link0">
		<inertial>
			<mass value="0.1"/>
			<origin xyz = "0 0 0" rpy="1.5707963267948966 0 0"/>
			<inertia ixx="1.0"
					 ixy="0.0"
					 ixz="0.0"
					 iyy="1.0"
					 iyz="0.0"
					 izz="1.0"/>
		</inertial>

		<visual name="link0_visual">
			<origin xyz = "0 0 0" rpy="1.5707963267948966 0 0"/>
			<geometry>
				<cylinder radius="0.025" length="0.1"/>
			</geometry>
		</visual>

		<collision name="link0_collision">
			<origin xyz = "0 0 0" rpy="1.5707963267948966 0 0"/>
			<geometry>
				<cylinder radius="0.025" length="0.1"/>
			</geometry>
		</collision>
	</link>

	
	<link name="link1">
		<inertial>
			<mass value="0.1"/>
			<origin xyz="0 -0.05 0" rpy="1.5707963267948966 0 0"/>
			<inertia ixx="1.0"
					 ixy="0.0"
					 ixz="0.0"
					 iyy="1.0"
					 iyz="0.0"
					 izz="1.0"/>
		</inertial>

		<visual name="link1_visual">
			<origin xyz = "0 -0.05 0" rpy="1.5707963267948966 0 0"/>
			<geometry>
				<cylinder radius="0.025" length="0.1"/>
			</geometry>
		</visual>

		<collision name="link1_collision">
			<origin xyz = "0 -0.05 0" rpy="1.5707963267948966 0 0"/>
			<geometry>
				<cylinder radius="0.025" length="0.1"/>
			</geometry>
		</collision>
	</link>

	<joint name="joint01" type="revolute">
		<parent link="link0"/>
		<child link="link1"/>
		
		<origin xyz="0 -0.05 0"/>
		
		<axis xyz="0 0 1"/>
		<limit lower="-0.7853981633974483" upper="0.7853981633974483" effort = "10.0" velocity="10.0"/>
	</joint>

	<transmission name="joint01_transmission">
		<type>transmission_interface/SimpleTransmission</type>

		<joint name="joint01">
			<hardwareInterface>hardware_interface/PositionJointInterface</hardwareInterface>
		</joint>

		<actuator name="joint01_motor">
			<hardwareInterface>hardware_interface/PositionJointInterface</hardwareInterface>
			<mechanicalReduction>1</mechanicalReduction>
		</actuator>
	</transmission>

	
	<link name="link2">
		<inertial>
			<mass value="0.1"/>
			<origin xyz="0 -0.05 0" rpy="1.5707963267948966 0 0"/>
			<inertia ixx="1.0"
					 ixy="0.0"
					 ixz="0.0"
					 iyy="1.0"
					 iyz="0.0"
					 izz="1.0"/>
		</inertial>

		<visual name="link2_visual">
			<origin xyz = "0 -0.05 0" rpy="1.5707963267948966 0 0"/>
			<geometry>
				<cylinder radius="0.025" length="0.1"/>
			</geometry>
		</visual>

		<collision name="link2_collision">
			<origin xyz = "0 -0.05 0" rpy="1.5707963267948966 0 0"/>
			<geometry>
				<cylinder radius="0.025" length="0.1"/>
			</geometry>
		</collision>
	</link>

	<joint name="joint12" type="revolute">
		<parent link="link1"/>
		<child link="link2"/>
		
		<origin xyz="0 -0.1 0"/>
		
		<axis xyz="0 0 1"/>
		<limit lower="-0.7853981633974483" upper="0.7853981633974483" effort = "10.0" velocity="10.0"/>
	</joint>

	<transmission name="joint12_transmission">
		<type>transmission_interface/SimpleTransmission</type>

		<joint name="joint12">
			<hardwareInterface>hardware_interface/PositionJointInterface</hardwareInterface>
		</joint>

		<actuator name="joint12_motor">
			<hardwareInterface>hardware_interface/PositionJointInterface</hardwareInterface>
			<mechanicalReduction>1</mechanicalReduction>
		</actuator>
	</transmission>

	
	<link name="link3">
		<inertial>
			<mass value="0.1"/>
			<origin xyz="0 -0.05 0" rpy="1.5707963267948966 0 0"/>
			<inertia ixx="1.0"
					 ixy="0.0"
					 ixz="0.0"
					 iyy="1.0"
					 iyz="0.0"
					 izz="1.0"/>
		</inertial>

		<visual name="link3_visual">
			<origin xyz = "0 -0.05 0" rpy="1.5707963267948966 0 0"/>
			<geometry>
				<cylinder radius="0.025" length="0.1"/>
			</geometry>
		</visual>

		<collision name="link3_collision">
			<origin xyz = "0 -0.05 0" rpy="1.5707963267948966 0 0"/>
			<geometry>
				<cylinder radius="0.025" length="0.1"/>
			</geometry>
		</collision>
	</link>

	<joint name="joint23" type="revolute">
		<parent link="link2"/>
		<child link="link3"/>
		
		<origin xyz="0 -0.1 0"/>
		
		<axis xyz="0 0 1"/>
		<limit lower="-0.7853981633974483" upper="0.7853981633974483" effort = "10.0" velocity="10.0"/>
	</joint>

	<transmission name="joint23_transmission">
		<type>transmission_interface/SimpleTransmission</type>

		<joint name="joint23">
			<hardwareInterface>hardware_interface/PositionJointInterface</hardwareInterface>
		</joint>

		<actuator name="joint23_motor">
			<hardwareInterface>hardware_interface/PositionJointInterface</hardwareInterface>
			<mechanicalReduction>1</mechanicalReduction>
		</actuator>
	</transmission>

	
	<link name="link4">
		<inertial>
			<mass value="0.1"/>
			<origin xyz="0 -0.05 0" rpy="1.5707963267948966 0 0"/>
			<inertia ixx="1.0"
					 ixy="0.0"
					 ixz="0.0"
					 iyy="1.0"
					 iyz="0.0"
					 izz="1.0"/>
		</inertial>

		<visual name="link4_visual">
			<origin xyz = "0 -0.05 0" rpy="1.5707963267948966 0 0"/>
			<geometry>
				<cylinder radius="0.025" length="0.1"/>
			</geometry>
		</visual>

		<collision name="link4_collision">
			<origin xyz = "0 -0.05 0" rpy="1.5707963267948966 0 0"/>
			<geometry>
				<cylinder radius="0.025" length="0.1"/>
			</geometry>
		</collision>
	</link>

	<joint name="joint34" type="revolute">
		<parent link="link3"/>
		<child link="link4"/>
		
		<origin xyz="0 -0.1 0"/>
		
		<axis xyz="0 0 1"/>
		<limit lower="-0.7853981633974483" upper="0.7853981633974483" effort = "10.0" velocity="10.0"/>
	</joint>

	<transmission name="joint34_transmission">
		<type>transmission_interface/SimpleTransmission</type>

		<joint name="joint34">
			<hardwareInterface>hardware_interface/PositionJointInterface</hardwareInterface>
		</joint>

		<actuator name="joint34_motor">
			<hardwareInterface>hardware_interface/PositionJointInterface</hardwareInterface>
			<mechanicalReduction>1</mechanicalReduction>
		</actuator>
	</transmission>

	
	<link name="link5">
		<inertial>
			<mass value="0.1"/>
			<origin xyz="0 -0.05 0" rpy="1.5707963267948966 0 0"/>
			<inertia ixx="1.0"
					 ixy="0.0"
					 ixz="0.0"
					 iyy="1.0"
					 iyz="0.0"
					 izz="1.0"/>
		</inertial>

		<visual name="link5_visual">
			<origin xyz = "0 -0.05 0" rpy="1.5707963267948966 0 0"/>
			<geometry>
				<cylinder radius="0.025" length="0.1"/>
			</geometry>
		</visual>

		<collision name="link5_collision">
			<origin xyz = "0 -0.05 0" rpy="1.5707963267948966 0 0"/>
			<geometry>
				<cylinder radius="0.025" length="0.1"/>
			</geometry>
		</collision>
	</link>

	<joint name="joint45" type="revolute">
		<parent link="link4"/>
		<child link="link5"/>
		
		<origin xyz="0 -0.1 0"/>
		
		<axis xyz="0 0 1"/>
		<limit lower="-0.7853981633974483" upper="0.7853981633974483" effort = "10.0" velocity="10.0"/>
	</joint>

	<transmission name="joint45_transmission">
		<type>transmission_interface/SimpleTransmission</type>

		<joint name="joint45">
			<hardwareInterface>hardware_interface/PositionJointInterface</hardwareInterface>
		</joint>

		<actuator name="joint45_motor">
			<hardwareInterface>hardware_interface/PositionJointInterface</hardwareInterface>
			<mechanicalReduction>1</mechanicalReduction>
		</actuator>
	</transmission>

	
	<link name="link6">
		<inertial>
			<mass value="0.1"/>
			<origin xyz="0 -0.05 0" rpy="1.5707963267948966 0 0"/>
			<inertia ixx="1.0"
					 ixy="0.0"
					 ixz="0.0"
					 iyy="1.0"
					 iyz="0.0"
					 izz="1.0"/>
		</inertial>

		<visual name="link6_visual">
			<origin xyz = "0 -0.05 0" rpy="1.5707963267948966 0 0"/>
			<geometry>
				<cylinder radius="0.025" length="0.1"/>
			</geometry>
		</visual>

		<collision name="link6_collision">
			<origin xyz = "0 -0.05 0" rpy="1.5707963267948966 0 0"/>
			<geometry>
				<cylinder radius="0.025" length="0.1"/>
			</geometry>
		</collision>
	</link>

	<joint name="joint56" type="revolute">
		<parent link="link5"/>
		<child link="link6"/>
		
		<origin xyz="0 -0.1 0"/>
		
		<axis xyz="0 0 1"/>
		<limit lower="-0.7853981633974483" upper="0.7853981633974483" effort = "10.0" velocity="10.0"/>
	</joint>

	<transmission name="joint56_transmission">
		<type>transmission_interface/SimpleTransmission</type>

		<joint name="joint56">
			<hardwareInterface>hardware_interface/PositionJointInterface</hardwareInterface>
		</joint>

		<actuator name="joint56_motor">
			<hardwareInterface>hardware_interface/PositionJointInterface</hardwareInterface>
			<mechanicalReduction>1</mechanicalReduction>
		</actuator>
	</transmission>

	
	<link name="link7">
		<inertial>
			<mass value="0.1"/>
			<origin xyz="0 -0.05 0" rpy="1.5707963267948966 0 0"/>
			<inertia ixx="1.0"
					 ixy="0.0"
					 ixz="0.0"
					 iyy="1.0"
					 iyz="0.0"
					 izz="1.0"/>
		</inertial>

		<visual name="link7_visual">
			<origin xyz = "0 -0.05 0" rpy="1.5707963267948966 0 0"/>
			<geometry>
				<cylinder radius="0.025" length="0.1"/>
			</geometry>
		</visual>

		<collision name="link7_collision">
			<origin xyz = "0 -0.05 0" rpy="1.5707963267948966 0 0"/>
			<geometry>
				<cylinder radius="0.025" length="0.1"/>
			</geometry>
		</collision>
	</link>

	<joint name="joint67" type="revolute">
		<parent link="link6"/>
		<child link="link7"/>
		
		<origin xyz="0 -0.1 0"/>
		
		<axis xyz="0 0 1"/>
		<limit lower="-0.7853981633974483" upper="0.7853981633974483" effort = "10.0" velocity="10.0"/>
	</joint>

	<transmission name="joint67_transmission">
		<type>transmission_interface/SimpleTransmission</type>

		<joint name="joint67">
			<hardwareInterface>hardware_interface/PositionJointInterface</hardwareInterface>
		</joint>

		<actuator name="joint67_motor">
			<hardwareInterface>hardware_interface/PositionJointInterface</hardwareInterface>
			<mechanicalReduction>1</mechanicalReduction>
		</actuator>
	</transmission>

	
	<link name="link8">
		<inertial>
			<mass value="0.1"/>
			<origin xyz="0 -0.05 0" rpy="1.5707963267948966 0 0"/>
			<inertia ixx="1.0"
					 ixy="0.0"
					 ixz="0.0"
					 iyy="1.0"
					 iyz="0.0"
					 izz="1.0"/>
		</inertial>

		<visual name="link8_visual">
			<origin xyz = "0 -0.05 0" rpy="1.5707963267948966 0 0"/>
			<geometry>
				<cylinder radius="0.025" length="0.1"/>
			</geometry>
		</visual>

		<collision name="link8_collision">
			<origin xyz = "0 -0.05 0" rpy="1.5707963267948966 0 0"/>
			<geometry>
				<cylinder radius="0.025" length="0.1"/>
			</geometry>
		</collision>
	</link>

	<joint name="joint78" type="revolute">
		<parent link="link7"/>
		<child link="link8"/>
		
		<origin xyz="0 -0.1 0"/>
		
		<axis xyz="0 0 1"/>
		<limit lower="-0.7853981633974483" upper="0.7853981633974483" effort = "10.0" velocity="10.0"/>
	</joint>

	<transmission name="joint78_transmission">
		<type>transmission_interface/SimpleTransmission</type>

		<joint name="joint78">
			<hardwareInterface>hardware_interface/PositionJointInterface</hardwareInterface>
		</joint>

		<actuator name="joint78_motor">
			<hardwareInterface>hardware_interface/PositionJointInterface</hardwareInterface>
			<mechanicalReduction>1</mechanicalReduction>
		</actuator>
	</transmission>

	
	<link name="link9">
		<inertial>
			<mass value="0.1"/>
			<origin xyz="0 -0.05 0" rpy="1.5707963267948966 0 0"/>
			<inertia ixx="1.0"
					 ixy="0.0"
					 ixz="0.0"
					 iyy="1.0"
					 iyz="0.0"
					 izz="1.0"/>
		</inertial>

		<visual name="link9_visual">
			<origin xyz = "0 -0.05 0" rpy="1.5707963267948966 0 0"/>
			<geometry>
				<cylinder radius="0.025" length="0.1"/>
			</geometry>
		</visual>

		<collision name="link9_collision">
			<origin xyz = "0 -0.05 0" rpy="1.5707963267948966 0 0"/>
			<geometry>
				<cylinder radius="0.025" length="0.1"/>
			</geometry>
		</collision>
	</link>

	<joint name="joint89" type="revolute">
		<parent link="link8"/>
		<child link="link9"/>
		
		<origin xyz="0 -0.1 0"/>
		
		<axis xyz="0 0 1"/>
		<limit lower="-0.7853981633974483" upper="0.7853981633974483" effort = "10.0" velocity="10.0"/>
	</joint>

	<transmission name="joint89_transmission">
		<type>transmission_interface/SimpleTransmission</type>

		<joint name="joint89">
			<hardwareInterface>hardware_interface/PositionJointInterface</hardwareInterface>
		</joint>

		<actuator name="joint89_motor">
			<hardwareInterface>hardware_interface/PositionJointInterface</hardwareInterface>
			<mechanicalReduction>1</mechanicalReduction>
		</actuator>
	</transmission>

	
	<link name="link10">
		<inertial>
			<mass value="0.1"/>
			<origin xyz="0 -0.05 0" rpy="1.5707963267948966 0 0"/>
			<inertia ixx="1.0"
					 ixy="0.0"
					 ixz="0.0"
					 iyy="1.0"
					 iyz="0.0"
					 izz="1.0"/>
		</inertial>

		<visual name="link10_visual">
			<origin xyz = "0 -0.05 0" rpy="1.5707963267948966 0 0"/>
			<geometry>
				<cylinder radius="0.025" length="0.1"/>
			</geometry>
		</visual>

		<collision name="link10_collision">
			<origin xyz = "0 -0.05 0" rpy="1.5707963267948966 0 0"/>
			<geometry>
				<cylinder radius="0.025" length="0.1"/>
			</geometry>
		</collision>
	</link>

	<joint name="joint910" type="revolute">
		<parent link="link9"/>
		<child link="link10"/>
		
		<origin xyz="0 -0.1 0"/>
		
		<axis xyz="0 0 1"/>
		<limit lower="-0.7853981633974483" upper="0.7853981633974483" effort = "10.0" velocity="10.0"/>
	</joint>

	<transmission name="joint910_transmission">
		<type>transmission_interface/SimpleTransmission</type>

		<joint name="joint910">
			<hardwareInterface>hardware_interface/PositionJointInterface</hardwareInterface>
		</joint>

		<actuator name="joint910_motor">
			<hardwareInterface>hardware_interface/PositionJointInterface</hardwareInterface>
			<mechanicalReduction>1</mechanicalReduction>
		</actuator>
	</transmission>

	
	<link name="link11">
		<inertial>
			<mass value="0.1"/>
			<origin xyz="0 -0.05 0" rpy="1.5707963267948966 0 0"/>
			<inertia ixx="1.0"
					 ixy="0.0"
					 ixz="0.0"
					 iyy="1.0"
					 iyz="0.0"
					 izz="1.0"/>
		</inertial>

		<visual name="link11_visual">
			<origin xyz = "0 -0.05 0" rpy="1.5707963267948966 0 0"/>
			<geometry>
				<cylinder radius="0.025" length="0.1"/>
			</geometry>
		</visual>

		<collision name="link11_collision">
			<origin xyz = "0 -0.05 0" rpy="1.5707963267948966 0 0"/>
			<geometry>
				<cylinder radius="0.025" length="0.1"/>
			</geometry>
		</collision>
	</link>

	<joint name="joint1011" type="revolute">
		<parent link="link10"/>
		<child link="link11"/>
		
		<origin xyz="0 -0.1 0"/>
		
		<axis xyz="0 0 1"/>
		<limit lower="-0.7853981633974483" upper="0.7853981633974483" effort = "10.0" velocity="10.0"/>
	</joint>

	<transmission name="joint1011_transmission">
		<type>transmission_interface/SimpleTransmission</type>

		<joint name="joint1011">
			<hardwareInterface>hardware_interface/PositionJointInterface</hardwareInterface>
		</joint>

		<actuator name="joint1011_motor">
			<hardwareInterface>hardware_interface/PositionJointInterface</hardwareInterface>
			<mechanicalReduction>1</mechanicalReduction>
		</actuator>
	</transmission>

	
	<link name="link12">
		<inertial>
			<mass value="0.1"/>
			<origin xyz="0 -0.05 0" rpy="1.5707963267948966 0 0"/>
			<inertia ixx="1.0"
					 ixy="0.0"
					 ixz="0.0"
					 iyy="1.0"
					 iyz="0.0"
					 izz="1.0"/>
		</inertial>

		<visual name="link12_visual">
			<origin xyz = "0 -0.05 0" rpy="1.5707963267948966 0 0"/>
			<geometry>
				<cylinder radius="0.025" length="0.1"/>
			</geometry>
		</visual>

		<collision name="link12_collision">
			<origin xyz = "0 -0.05 0" rpy="1.5707963267948966 0 0"/>
			<geometry>
				<cylinder radius="0.025" length="0.1"/>
			</geometry>
		</collision>
	</link>

	<joint name="joint1112" type="revolute">
		<parent link="link11"/>
		<child link="link12"/>
		
		<origin xyz="0 -0.1 0"/>
		
		<axis xyz="0 0 1"/>
		<limit lower="-0.7853981633974483" upper="0.7853981633974483" effort = "10.0" velocity="10.0"/>
	</joint>

	<transmission name="joint1112_transmission">
		<type>transmission_interface/SimpleTransmission</type>

		<joint name="joint1112">
			<hardwareInterface>hardware_interface/PositionJointInterface</hardwareInterface>
		</joint>

		<actuator name="joint1112_motor">
			<hardwareInterface>hardware_interface/PositionJointInterface</hardwareInterface>
			<mechanicalReduction>1</mechanicalReduction>
		</actuator>
	</transmission>

	
	<link name="link13">
		<inertial>
			<mass value="0.1"/>
			<origin xyz="0 -0.05 0" rpy="1.5707963267948966 0 0"/>
			<inertia ixx="1.0"
					 ixy="0.0"
					 ixz="0.0"
					 iyy="1.0"
					 iyz="0.0"
					 izz="1.0"/>
		</inertial>

		<visual name="link13_visual">
			<origin xyz = "0 -0.05 0" rpy="1.5707963267948966 0 0"/>
			<geometry>
				<cylinder radius="0.025" length="0.1"/>
			</geometry>
		</visual>

		<collision name="link13_collision">
			<origin xyz = "0 -0.05 0" rpy="1.5707963267948966 0 0"/>
			<geometry>
				<cylinder radius="0.025" length="0.1"/>
			</geometry>
		</collision>
	</link>

	<joint name="joint1213" type="revolute">
		<parent link="link12"/>
		<child link="link13"/>
		
		<origin xyz="0 -0.1 0"/>
		
		<axis xyz="0 0 1"/>
		<limit lower="-0.7853981633974483" upper="0.7853981633974483" effort = "10.0" velocity="10.0"/>
	</joint>

	<transmission name="joint1213_transmission">
		<type>transmission_interface/SimpleTransmission</type>

		<joint name="joint1213">
			<hardwareInterface>hardware_interface/PositionJointInterface</hardwareInterface>
		</joint>

		<actuator name="joint1213_motor">
			<hardwareInterface>hardware_interface/PositionJointInterface</hardwareInterface>
			<mechanicalReduction>1</mechanicalReduction>
		</actuator>
	</transmission>

	
	<link name="link14">
		<inertial>
			<mass value="0.1"/>
			<origin xyz="0 -0.05 0" rpy="1.5707963267948966 0 0"/>
			<inertia ixx="1.0"
					 ixy="0.0"
					 ixz="0.0"
					 iyy="1.0"
					 iyz="0.0"
					 izz="1.0"/>
		</inertial>

		<visual name="link14_visual">
			<origin xyz = "0 -0.05 0" rpy="1.5707963267948966 0 0"/>
			<geometry>
				<cylinder radius="0.025" length="0.1"/>
			</geometry>
		</visual>

		<collision name="link14_collision">
			<origin xyz = "0 -0.05 0" rpy="1.5707963267948966 0 0"/>
			<geometry>
				<cylinder radius="0.025" length="0.1"/>
			</geometry>
		</collision>
	</link>

	<joint name="joint1314" type="revolute">
		<parent link="link13"/>
		<child link="link14"/>
		
		<origin xyz="0 -0.1 0"/>
		
		<axis xyz="0 0 1"/>
		<limit lower="-0.7853981633974483" upper="0.7853981633974483" effort = "10.0" velocity="10.0"/>
	</joint>

	<transmission name="joint1314_transmission">
		<type>transmission_interface/SimpleTransmission</type>

		<joint name="joint1314">
			<hardwareInterface>hardware_interface/PositionJointInterface</hardwareInterface>
		</joint>

		<actuator name="joint1314_motor">
			<hardwareInterface>hardware_interface/PositionJointInterface</hardwareInterface>
			<mechanicalReduction>1</mechanicalReduction>
		</actuator>
	</transmission>

	
	<link name="link15">
		<inertial>
			<mass value="0.1"/>
			<origin xyz="0 -0.05 0" rpy="1.5707963267948966 0 0"/>
			<inertia ixx="1.0"
					 ixy="0.0"
					 ixz="0.0"
					 iyy="1.0"
					 iyz="0.0"
					 izz="1.0"/>
		</inertial>

		<visual name="link15_visual">
			<origin xyz = "0 -0.05 0" rpy="1.5707963267948966 0 0"/>
			<geometry>
				<cylinder radius="0.025" length="0.1"/>
			</geometry>
		</visual>

		<collision name="link15_collision">
			<origin xyz = "0 -0.05 0" rpy="1.5707963267948966 0 0"/>
			<geometry>
				<cylinder radius="0.025" length="0.1"/>
			</geometry>
		</collision>
	</link>

	<joint name="joint1415" type="revolute">
		<parent link="link14"/>
		<child link="link15"/>
		
		<origin xyz="0 -0.1 0"/>
		
		<axis xyz="0 0 1"/>
		<limit lower="-0.7853981633974483" upper="0.7853981633974483" effort = "10.0" velocity="10.0"/>
	</joint>

	<transmission name="joint1415_transmission">
		<type>transmission_interface/SimpleTransmission</type>

		<joint name="joint1415">
			<hardwareInterface>hardware_interface/PositionJointInterface</hardwareInterface>
		</joint>

		<actuator name="joint1415_motor">
			<hardwareInterface>hardware_interface/PositionJointInterface</hardwareInterface>
			<mechanicalReduction>1</mechanicalReduction>
		</actuator>
	</transmission>

	
	<link name="link16">
		<inertial>
			<mass value="0.1"/>
			<origin xyz="0 -0.05 0" rpy="1.5707963267948966 0 0"/>
			<inertia ixx="1.0"
					 ixy="0.0"
					 ixz="0.0"
					 iyy="1.0"
					 iyz="0.0"
					 izz="1.0"/>
		</inertial>

		<visual name="link16_visual">
			<origin xyz = "0 -0.05 0" rpy="1.5707963267948966 0 0"/>
			<geometry>
				<cylinder radius="0.025" length="0.1"/>
			</geometry>
		</visual>

		<collision name="link16_collision">
			<origin xyz = "0 -0.05 0" rpy="1.5707963267948966 0 0"/>
			<geometry>
				<cylinder radius="0.025" length="0.1"/>
			</geometry>
		</collision>
	</link>

	<joint name="joint1516" type="revolute">
		<parent link="link15"/>
		<child link="link16"/>
		
		<origin xyz="0 -0.1 0"/>
		
		<axis xyz="0 0 1"/>
		<limit lower="-0.7853981633974483" upper="0.7853981633974483" effort = "10.0" velocity="10.0"/>
	</joint>

	<transmission name="joint1516_transmission">
		<type>transmission_interface/SimpleTransmission</type>

		<joint name="joint1516">
			<hardwareInterface>hardware_interface/PositionJointInterface</hardwareInterface>
		</joint>

		<actuator name="joint1516_motor">
			<hardwareInterface>hardware_interface/PositionJointInterface</hardwareInterface>
			<mechanicalReduction>1</mechanicalReduction>
		</actuator>
	</transmission>

	
	<link name="link17">
		<inertial>
			<mass value="0.1"/>
			<origin xyz="0 -0.05 0" rpy="1.5707963267948966 0 0"/>
			<inertia ixx="1.0"
					 ixy="0.0"
					 ixz="0.0"
					 iyy="1.0"
					 iyz="0.0"
					 izz="1.0"/>
		</inertial>

		<visual name="link17_visual">
			<origin xyz = "0 -0.05 0" rpy="1.5707963267948966 0 0"/>
			<geometry>
				<cylinder radius="0.025" length="0.1"/>
			</geometry>
		</visual>

		<collision name="link17_collision">
			<origin xyz = "0 -0.05 0" rpy="1.5707963267948966 0 0"/>
			<geometry>
				<cylinder radius="0.025" length="0.1"/>
			</geometry>
		</collision>
	</link>

	<joint name="joint1617" type="revolute">
		<parent link="link16"/>
		<child link="link17"/>
		
		<origin xyz="0 -0.1 0"/>
		
		<axis xyz="0 0 1"/>
		<limit lower="-0.7853981633974483" upper="0.7853981633974483" effort = "10.0" velocity="10.0"/>
	</joint>

	<transmission name="joint1617_transmission">
		<type>transmission_interface/SimpleTransmission</type>

		<joint name="joint1617">
			<hardwareInterface>hardware_interface/PositionJointInterface</hardwareInterface>
		</joint>

		<actuator name="joint1617_motor">
			<hardwareInterface>hardware_interface/PositionJointInterface</hardwareInterface>
			<mechanicalReduction>1</mechanicalReduction>
		</actuator>
	</transmission>

	
	<link name="link18">
		<inertial>
			<mass value="0.1"/>
			<origin xyz="0 -0.05 0" rpy="1.5707963267948966 0 0"/>
			<inertia ixx="1.0"
					 ixy="0.0"
					 ixz="0.0"
					 iyy="1.0"
					 iyz="0.0"
					 izz="1.0"/>
		</inertial>

		<visual name="link18_visual">
			<origin xyz = "0 -0.05 0" rpy="1.5707963267948966 0 0"/>
			<geometry>
				<cylinder radius="0.025" length="0.1"/>
			</geometry>
		</visual>

		<collision name="link18_collision">
			<origin xyz = "0 -0.05 0" rpy="1.5707963267948966 0 0"/>
			<geometry>
				<cylinder radius="0.025" length="0.1"/>
			</geometry>
		</collision>
	</link>

	<joint name="joint1718" type="revolute">
		<parent link="link17"/>
		<child link="link18"/>
		
		<origin xyz="0 -0.1 0"/>
		
		<axis xyz="0 0 1"/>
		<limit lower="-0.7853981633974483" upper="0.7853981633974483" effort = "10.0" velocity="10.0"/>
	</joint>

	<transmission name="joint1718_transmission">
		<type>transmission_interface/SimpleTransmission</type>

		<joint name="joint1718">
			<hardwareInterface>hardware_interface/PositionJointInterface</hardwareInterface>
		</joint>

		<actuator name="joint1718_motor">
			<hardwareInterface>hardware_interface/PositionJointInterface</hardwareInterface>
			<mechanicalReduction>1</mechanicalReduction>
		</actuator>
	</transmission>

	
	<link name="link19">
		<inertial>
			<mass value="0.1"/>
			<origin xyz="0 -0.05 0" rpy="1.5707963267948966 0 0"/>
			<inertia ixx="1.0"
					 ixy="0.0"
					 ixz="0.0"
					 iyy="1.0"
					 iyz="0.0"
					 izz="1.0"/>
		</inertial>

		<visual name="link19_visual">
			<origin xyz = "0 -0.05 0" rpy="1.5707963267948966 0 0"/>
			<geometry>
				<cylinder radius="0.025" length="0.1"/>
			</geometry>
		</visual>

		<collision name="link19_collision">
			<origin xyz = "0 -0.05 0" rpy="1.5707963267948966 0 0"/>
			<geometry>
				<cylinder radius="0.025" length="0.1"/>
			</geometry>
		</collision>
	</link>

	<joint name="joint1819" type="revolute">
		<parent link="link18"/>
		<child link="link19"/>
		
		<origin xyz="0 -0.1 0"/>
		
		<axis xyz="0 0 1"/>
		<limit lower="-0.7853981633974483" upper="0.7853981633974483" effort = "10.0" velocity="10.0"/>
	</joint>

	<transmission name="joint1819_transmission">
		<type>transmission_interface/SimpleTransmission</type>

		<joint name="joint1819">
			<hardwareInterface>hardware_interface/PositionJointInterface</hardwareInterface>
		</joint>

		<actuator name="joint1819_motor">
			<hardwareInterface>hardware_interface/PositionJointInterface</hardwareInterface>
			<mechanicalReduction>1</mechanicalReduction>
		</actuator>
	</transmission>

	
	<link name="link20">
		<inertial>
			<mass value="0.1"/>
			<origin xyz="0 -0.05 0" rpy="1.5707963267948966 0 0"/>
			<inertia ixx="1.0"
					 ixy="0.0"
					 ixz="0.0"
					 iyy="1.0"
					 iyz="0.0"
					 izz="1.0"/>
		</inertial>

		<visual name="link20_visual">
			<origin xyz = "0 -0.05 0" rpy="1.5707963267948966 0 0"/>
			<geometry>
				<cylinder radius="0.025" length="0.1"/>
			</geometry>
		</visual>

		<collision name="link20_collision">
			<origin xyz = "0 -0.05 0" rpy="1.5707963267948966 0 0"/>
			<geometry>
				<cylinder radius="0.025" length="0.1"/>
			</geometry>
		</collision>
	</link>

	<joint name="joint1920" type="revolute">
		<parent link="link19"/>
		<child link="link20"/>
		
		<origin xyz="0 -0.1 0"/>
		
		<axis xyz="0 0 1"/>
		<limit lower="-0.7853981633974483" upper="0.7853981633974483" effort = "10.0" velocity="10.0"/>
	</joint>

	<transmission name="joint1920_transmission">
		<type>transmission_interface/SimpleTransmission</type>

		<joint name="joint1920">
			<hardwareInterface>hardware_interface/PositionJointInterface</hardwareInterface>
		</joint>

		<actuator name="joint1920_motor">
			<hardwareInterface>hardware_interface/PositionJointInterface</hardwareInterface>
			<mechanicalReduction>1</mechanicalReduction>
		</actuator>
	</transmission>

	

	<gazebo>
		<static>false</static>

		<plugin name="gazebo_ros_control" filename="libgazebo_ros_control.so">
			<robotNamespace>/slither</robotNamespace>
		</plugin>
	</gazebo>

</robot>